Workbook

Sheet Assets
B1: Assets
B2: Cash
B3: Rent paid in advance (the lease) | D3: -1300
B4: Park Tool repair stand | D4: -200
B5: Repair, customer paid | D5: 340
B6: Repair, customer paid | D6: 180
B7: Repair, customer paid | D7: 80
B8: Repair, customer paid | D8: 140
B9: Repair, customer paid | D9: 130
B10: Smith's deposit received | D10: 220
B11: Repair, customer paid | D11: 100
B12: Repair, customer paid | D12: 150
B13: Covered from your personal funds | D13: 160
B14: Deposited to open the LLC bank account | D14: 1300
B15: Balance, June 1, 2026 | D15: =SUM(D3:D14) -> 1300
B16: Repair collected — Dana R. | D16: 120
B17: Repair collected — Marcus T. | D17: 150
B18: Repair collected — Priya S. | D18: 270
B19: Repair collected — Liam O. | D19: 300
B20: Repair collected — Sofia M. | D20: 150
B21: Repair collected — Jamal W. | D21: 360
B22: Repair collected — Erin K. | D22: 225
B23: Repair collected — Noah B. | D23: 210
B24: Repair collected — Grace L. | D24: 240
B25: Repair collected — Theo H. | D25: 240
B26: Repair collected — Maya P. | D26: 450
B27: Repair collected — Owen C. | D27: 360
... B43: Money taken out for personal use | D43: -600
B44: Balance, August 31, 2026 | D44: =D15+SUM(D16:D43) -> 620
B46: Accounts Receivable
B47: Ridgeline Trail Crew — finished Aug 28, net 15 (unpaid) | D47: 300
B48: Balance, August 31, 2026 | D48: =SUM(D47:D47) -> 300
B50: Right of Use
B51: Last month's rent, paid in advance (on deposit) | D51: 650
B52: Balance, June 1, 2026 | D52: =SUM(D51:D51) -> 650
B53: Balance, August 31, 2026 | D53: =D52 -> 650
B55: Parts
B56: Chains | D56: 50
B57: Brake pads | D57: 40
B58: Derailleur cables | D58: 20
...

Sheet Liabilities
B1: Liabilities
B2: Credit Card
B3: Charged — hand tools | D3: 300
B4: Charged — air compressor | D4: 180
B5: Charged — parts washer | D5: 130
B6: Charged — wheel-truing stand | D6: 170
B7: Charged — fixtures | D7: 750
B8: Charged — parts (QBP order) | D8: 500
B9: Balance, June 1, 2026 | D9: =SUM(D3:D8) -> 2030
B10: Paid off in full this season | D10: -2030
B11: Balance, August 31, 2026 | D11: =D9+SUM(D10:D10) -> 0
B13: Customer Deposit
B14: Smith's advance for a custom frame | D14: 220
B15: Balance, June 1, 2026 | D15: =SUM(D14:D14) -> 220
B16: Built and delivered Smith's frame — no longer owed | D16: -220
B17: Balance, August 31, 2026 | D17: =D15+SUM(D16:D16) -> 0

Sheet Reasons
B1: Reasons — Members' Capital
B2: CONTRIBUTED
B3: Cash — covered from your personal funds (May) | D3: 160
B4: Laptop — brought from home (May) | D4: 610
B5: Equipment — gear from home — grinder, headset press, shop vacuum (May) | D5: 220
B6: Cash — deposited to open the LLC bank account (June 1) | D6: 1300
B7: Balance, June 1, 2026 | D7: =SUM(D3:D6) -> 2290
B8: Balance, August 31, 2026 | D8: =D7 -> 2290
B10: GENERATED
B11: Repair collected — Brake job + Tune-up + Tire mounting ×2 @ $70 | D11: 340
B12: Repair collected — Walk-ins — mixed work (no itemized detail) | D12: 180
B13: Repair collected — Tune-up | D13: 80
B14: Repair collected — Brake overhaul | D14: 140
B15: Repair collected — Chain + cassette replacement | D15: 130
B16: Repair collected — Tune-up + minor repair | D16: 100
B17: Repair collected — Custom wheel work + new spokes | D17: 150
B18: Parts used — May | D18: -300
B19: Rent used — May | D19: -650
B20: Balance, June 1, 2026 | D20: =SUM(D11:D19) -> 170
B21: Rent used — June | D21: -650
B22: Repair collected — Dana R. | D22: 120
B23: Parts used — Dana R. | D23: -10
B24: Repair collected — Marcus T. | D24: 150
B25: Repair collected — Priya S. | D25: 270
B26: Parts used — Priya S. | D26: -25
B27: Repair collected — Liam O. | D27: 300
B28: Parts used — Liam O. | D28: -95
B29: Repair collected — Sofia M. | D29: 150
B30: Repair collected — Jamal W. | D30: 360
B31: Parts used — Jamal W. | D31: -60
B32: Repair collected — Erin K. | D32: 225
... B65: Depreciation — laptop, Summer 2026 | D65: -30
B66: Balance, August 31, 2026 | D66: =D20+SUM(D21:D65) -> 2810
B68: WITHDRAWN
B69: Owner's draw — money taken out for personal use | D69: -600
B70: Balance, August 31, 2026 | D70: =SUM(D69:D69) -> -600

Sheet Balance Sheet
B1: Balance Sheet
C2: June 1, 2026 | D2: August 31, 2026
B3: Assets
B4: Cash | C4: =Assets!D15 -> 1300 | D4: =Assets!D44 -> 620
B5: Accounts Receivable | C5: — | D5: =Assets!D48 -> 300
B6: Right of Use | C6: =Assets!D52 -> 650 | D6: =Assets!D53 -> 650
B7: Parts | C7: =Assets!D63 -> 200 | D7: =Assets!D98 -> 200
B8: Tools & Repair Equipment | C8: =Assets!D114 -> 1200 | D8: =Assets!D117 -> 1440
B9: Fixtures | C9: =Assets!D124 -> 750 | D9: =Assets!D126 -> 710
B10: Laptop | C10: =Assets!D130 -> 610 | D10: =Assets!D132 -> 580
B11: Total Assets | C11: =SUM(C4:C10) -> 4710 | D11: =SUM(D4:D10) -> 4500
B12: Liabilities
B13: Credit Card | C13: =Liabilities!D9 -> 2030 | D13: =Liabilities!D11 -> 0
B14: Customer Deposit | C14: =Liabilities!D15 -> 220 | D14: =Liabilities!D17 -> 0
B15: Total Liabilities | C15: =SUM(C13:C14) -> 2250 | D15: =SUM(D13:D14) -> 0
B16: Members' Capital
B17: Contributed | C17: =Reasons!D7 -> 2290 | D17: =Reasons!D8 -> 2290
B18: Generated | C18: =Reasons!D20 -> 170 | D18: =Reasons!D66 -> 2810
B19: Withdrawn | C19: — | D19: =Reasons!D70 -> -600
B20: Total Members' Capital | C20: =SUM(C17:C19) -> 2460 | D20: =SUM(D17:D19) -> 4500

Sheet Income Statement
B1: Income Statement
B2: Rent used — June | D2: -650
B3: Repair collected — Dana R. | D3: 120
B4: Parts used — Dana R. | D4: -10
B5: Repair collected — Marcus T. | D5: 150
B6: Repair collected — Priya S. | D6: 270
B7: Parts used — Priya S. | D7: -25
B8: Repair collected — Liam O. | D8: 300
B9: Parts used — Liam O. | D9: -95
B10: Repair collected — Sofia M. | D10: 150
B11: Repair collected — Jamal W. | D11: 360
B12: Parts used — Jamal W. | D12: -60
B13: Repair collected — Erin K. | D13: 225
... B46: Depreciation — laptop, Summer 2026 | D46: -30

Sheet St_Members_Capital
B1: Statement of Member's Capital
B3: CONTRIBUTED
B4: Cash — covered from your personal funds (May) | D4: 160
B5: Laptop — brought from home (May) | D5: 610
B6: Equipment — gear from home — grinder, headset press, shop vacuum (May) | D6: 220
B7: Cash — deposited to open the LLC bank account (June 1) | D7: 1300
B8: Balance, June 1, 2026 | D8: =SUM(D4:D7) -> 2290
B9: Balance, August 31, 2026 | D9: =D8 -> 2290
B11: GENERATED
B12: Repair collected — Brake job + Tune-up + Tire mounting ×2 @ $70 | D12: 340
B13: Repair collected — Walk-ins — mixed work (no itemized detail) | D13: 180
B14: Repair collected — Tune-up | D14: 80
B15: Repair collected — Brake overhaul | D15: 140
B16: Repair collected — Chain + cassette replacement | D16: 130
B17: Repair collected — Tune-up + minor repair | D17: 100
B18: Repair collected — Custom wheel work + new spokes | D18: 150
B19: Parts used — May | D19: -300
B20: Rent used — May | D20: -650
B21: Balance, June 1, 2026 | D21: =SUM(D12:D20) -> 170
B22: Rent used — June | D22: -650
B23: Repair collected — Dana R. | D23: 120
B24: Parts used — Dana R. | D24: -10
B25: Repair collected — Marcus T. | D25: 150
B26: Repair collected — Priya S. | D26: 270
B27: Parts used — Priya S. | D27: -25
B28: Repair collected — Liam O. | D28: 300
B29: Parts used — Liam O. | D29: -95
B30: Repair collected — Sofia M. | D30: 150
B31: Repair collected — Jamal W. | D31: 360
B32: Parts used — Jamal W. | D32: -60
B33: Repair collected — Erin K. | D33: 225
... B66: Depreciation — laptop, Summer 2026 | D66: -30
B67: Balance, August 31, 2026 | D67: =D21+SUM(D22:D66) -> 2810
B69: WITHDRAWN
B70: Owner's draw — money taken out for personal use | D70: -600
B71: Balance, August 31, 2026 | D71: =SUM(D70:D70) -> -600

Sheet Cash_Flow_Statement
B1: Cash Flow Statement
B3: Repair collected — Dana R. | D3: 120
B4: Repair collected — Marcus T. | D4: 150
B5: Repair collected — Priya S. | D5: 270
B6: Repair collected — Liam O. | D6: 300
B7: Repair collected — Sofia M. | D7: 150
B8: Repair collected — Jamal W. | D8: 360
B9: Repair collected — Erin K. | D9: 225
B10: Repair collected — Noah B. | D10: 210
B11: Repair collected — Grace L. | D11: 240
B12: Repair collected — Theo H. | D12: 240
B13: Repair collected — Maya P. | D13: 450
B14: Repair collected — Owen C. | D14: 360
... B30: Money taken out for personal use | D30: -600
